ERROR:root:에러 발생: 'SeoulRtd.citydata'
Traceback (most recent call last):
  File "c:\Users\rjy12\OneDrive\바탕 화면\realtime_seoul\datapipeline_process.py", line 76, in <module>
    data = get_data_from_api()
  File "c:\Users\rjy12\OneDrive\바탕 화면\realtime_seoul\datapipeline_process.py", line 36, in get_data_from_api
    population = json_response["SeoulRtd.citydata"]["CITYDATA"]["LIVE_PPLTN_STTS"]["LIVE_PPLTN_STTS"]
KeyError: 'SeoulRtd.citydata'
ERROR:root:에러 발생: HTTPConnectionPool(host='openapi.seoul.go.kr', port=8088): Max retries exceeded with url: /487256555172797535385047436d45/xml/citydata/1/5/POI084 (Caused by NewConnectionError('<urllib3.connection.HTTPConnection object at 0x000002683AC98070>: Failed to establish a new connection: [WinError 10060] 연결된 구성원으로부터 응답이 없어 연결하지 못했거나, 호스트로부터 응답이 없어 연결이 끊어졌습니다'))
Traceback (most recent call last):
  File "C:\Users\rjy12\anaconda3\lib\site-packages\urllib3\connection.py", line 174, in _new_conn
    conn = connection.create_connection(
  File "C:\Users\rjy12\anaconda3\lib\site-packages\urllib3\util\connection.py", line 95, in create_connection
    raise err
  File "C:\Users\rjy12\anaconda3\lib\site-packages\urllib3\util\connection.py", line 85, in create_connection
    sock.connect(sa)
TimeoutError: [WinError 10060] 연결된 구성원으로부터 응답이 없어 연결하지 못했거나, 호스트로부터 응답이 없어 연결이 끊어졌습니다

During handling of the above exception, another exception occurred:

Traceback (most recent call last):
  File "C:\Users\rjy12\anaconda3\lib\site-packages\urllib3\connectionpool.py", line 703, in urlopen
    httplib_response = self._make_request(
  File "C:\Users\rjy12\anaconda3\lib\site-packages\urllib3\connectionpool.py", line 398, in _make_request
    conn.request(method, url, **httplib_request_kw)
  File "C:\Users\rjy12\anaconda3\lib\site-packages\urllib3\connection.py", line 239, in request
    super(HTTPConnection, self).request(method, url, body=body, headers=headers)
  File "C:\Users\rjy12\anaconda3\lib\http\client.py", line 1285, in request
    self._send_request(method, url, body, headers, encode_chunked)
  File "C:\Users\rjy12\anaconda3\lib\http\client.py", line 1331, in _send_request
    self.endheaders(body, encode_chunked=encode_chunked)
  File "C:\Users\rjy12\anaconda3\lib\http\client.py", line 1280, in endheaders
    self._send_output(message_body, encode_chunked=encode_chunked)
  File "C:\Users\rjy12\anaconda3\lib\http\client.py", line 1040, in _send_output
    self.send(msg)
  File "C:\Users\rjy12\anaconda3\lib\http\client.py", line 980, in send
    self.connect()
  File "C:\Users\rjy12\anaconda3\lib\site-packages\urllib3\connection.py", line 205, in connect
    conn = self._new_conn()
  File "C:\Users\rjy12\anaconda3\lib\site-packages\urllib3\connection.py", line 186, in _new_conn
    raise NewConnectionError(
urllib3.exceptions.NewConnectionError: <urllib3.connection.HTTPConnection object at 0x000002683AC98070>: Failed to establish a new connection: [WinError 10060] 연결된 구성원으로부터 응답이 없어 연결하지 못했거나, 호스트로부터 응답이 없어 연결이 끊어졌습니다

During handling of the above exception, another exception occurred:

Traceback (most recent call last):
  File "C:\Users\rjy12\anaconda3\lib\site-packages\requests\adapters.py", line 489, in send
    resp = conn.urlopen(
  File "C:\Users\rjy12\anaconda3\lib\site-packages\urllib3\connectionpool.py", line 787, in urlopen
    retries = retries.increment(
  File "C:\Users\rjy12\anaconda3\lib\site-packages\urllib3\util\retry.py", line 592, in increment
    raise MaxRetryError(_pool, url, error or ResponseError(cause))
urllib3.exceptions.MaxRetryError: HTTPConnectionPool(host='openapi.seoul.go.kr', port=8088): Max retries exceeded with url: /487256555172797535385047436d45/xml/citydata/1/5/POI084 (Caused by NewConnectionError('<urllib3.connection.HTTPConnection object at 0x000002683AC98070>: Failed to establish a new connection: [WinError 10060] 연결된 구성원으로부터 응답이 없어 연결하지 못했거나, 호스트로부터 응답이 없어 연결이 끊어졌습니다'))

During handling of the above exception, another exception occurred:

Traceback (most recent call last):
  File "c:\Users\rjy12\OneDrive\바탕 화면\realtime_seoul\test.py", line 62, in <module>
    data = get_data_from_api()
  File "c:\Users\rjy12\OneDrive\바탕 화면\realtime_seoul\test.py", line 31, in get_data_from_api
    response = requests.get(url)
  File "C:\Users\rjy12\anaconda3\lib\site-packages\requests\api.py", line 73, in get
    return request("get", url, params=params, **kwargs)
  File "C:\Users\rjy12\anaconda3\lib\site-packages\requests\api.py", line 59, in request
    return session.request(method=method, url=url, **kwargs)
  File "C:\Users\rjy12\anaconda3\lib\site-packages\requests\sessions.py", line 587, in request
    resp = self.send(prep, **send_kwargs)
  File "C:\Users\rjy12\anaconda3\lib\site-packages\requests\sessions.py", line 701, in send
    r = adapter.send(request, **kwargs)
  File "C:\Users\rjy12\anaconda3\lib\site-packages\requests\adapters.py", line 565, in send
    raise ConnectionError(e, request=request)
requests.exceptions.ConnectionError: HTTPConnectionPool(host='openapi.seoul.go.kr', port=8088): Max retries exceeded with url: /487256555172797535385047436d45/xml/citydata/1/5/POI084 (Caused by NewConnectionError('<urllib3.connection.HTTPConnection object at 0x000002683AC98070>: Failed to establish a new connection: [WinError 10060] 연결된 구성원으로부터 응답이 없어 연결하지 못했거나, 호스트로부터 응답이 없어 연결이 끊어졌습니다'))
